<?xml version="1.0" ?>
<!-- =================================================================================== -->
<!-- |    This document was autogenerated by xacro from /home/radi/householder/src/mybot_description/urdf/mybot.xacro | -->
<!-- |    EDITING THIS FILE BY HAND IS NOT RECOMMENDED                                 | -->
<!-- =================================================================================== -->
<robot name="myrobot" xmlns:xacro="http://www.ros.org/wiki/xacro">
 
    <material name="black">
        <color rgba="0.0 0.0 0.0 1.0" />
    </material>
    <material name="blue">
        <color rgba="0.0 0.0 0.8 1.0" />
    </material>
    <material name="green">
        <color rgba="0.0 0.8 0.0 1.0" />
    </material>
    <material name="grey">
        <color rgba="0.2 0.2 0.2 1.0" />
    </material>
    <material name="orange">
        <color rgba="1.0 0.423529411765 0.0392156862745 1.0" />
    </material>
    <material name="brown">
        <color rgba="0.870588235294 0.811764705882 0.764705882353 1.0" />
    </material>
    <material name="red">
        <color rgba="0.8 0.0 0.0 1.0" />
    </material>
    <material name="white">
        <color rgba="1.0 1.0 1.0 1.0" />
    </material>
    <!--macro name="cylinder_inertia" params="m r h">
    <inertia  ixx="${m*(3*r*r+h*h)/12}" ixy = "0" ixz = "0"
      iyy="${m*(3*r*r+h*h)/12}" iyz = "0"
      izz="${m*r*r/2}"
    />
  </macro>

  <macro name="box_inertia" params="m x y z">
    <inertia  ixx="${m*(y*y+z*z)/12}" ixy = "0" ixz = "0"
      iyy="${m*(x*x+z*z)/12}" iyz = "0"
      izz="${m*(x*x+z*z)/12}"
    />
  </macro>

  <macro name="sphere_inertia" params="m r">
    <inertia  ixx="${2*m*r*r/5}" ixy = "0" ixz = "0"
      iyy="${2*m*r*r/5}" iyz = "0"
      izz="${2*m*r*r/5}"
    />
  </macro>







  <macro name="wheel" params="lr tY">

    <link name="${lr}_wheel">
      <collision>
        <origin xyz="0 0 0" rpy="0 ${PI/2} ${PI/2}" />
        <geometry>
          <cylinder length="${wheelWidth}" radius="${wheelRadius}"/>
        </geometry>
      </collision>

      <visual>
        <origin xyz="0 0 0" rpy="0 ${PI/2} ${PI/2}" />
        <geometry>
          <cylinder length="${wheelWidth}" radius="${wheelRadius}"/>
        </geometry>
        <material name="black"/>
      </visual>

      
<inertial>
        <origin xyz="0 0 0" rpy="0 ${PI/2} ${PI/2}" />
        <mass value="${wheelMass}"/>
        <cylinder_inertia m="${wheelMass}" r="${wheelRadius}" h="${wheelWidth}"/>
      </inertial>

    </link>

    <gazebo reference="${lr}_wheel">
      <mu1 value="1.0"/>
      <mu2 value="1.0"/>
      <kp  value="10000000.0" />
      <kd  value="1.0" />
      <fdir1 value="1 0 0"/>
      <material>Gazebo/Black</material>
    </gazebo>


    <joint name="${lr}_wheel_hinge" type="continuous">
      <parent link="chassis"/>
      <child link="${lr}_wheel"/>
    <origin xyz="${-wheelPos+chassisLength/2} ${tY*wheelWidth/2+tY*chassisWidth/2} ${wheelRadius}" rpy="0 0 0" />
      <axis xyz="0 1 0" rpy="0 0 0" />
      <limit effort="10000" velocity="10000"/>
      <joint_properties damping="0.0" friction="0.0"/>
    </joint>


    <transmission name="${lr}_trans">
      <type>transmission_interface/SimpleTransmission</type>
      <joint name="${lr}_wheel_hinge">
        <hardwareInterface>EffortJointInterface</hardwareInterface>
      </joint>
      <actuator name="${lr}Motor">
        <hardwareInterface>EffortJointInterface</hardwareInterface>
        <mechanicalReduction>10</mechanicalReduction>
      </actuator>
    </transmission>

  </macro-->
    <link name="root" />
    <link name="chassis">
        
<inertial>
            <mass value="10.0" />
            <origin rpy=" 0 0 0" xyz="0 0 0" />
            <inertia ixx="0.5" ixy="0" ixz="0" iyy="1.0" iyz="0" izz="0.1" />
        </inertial>

        <collision name="collision">
            <origin rpy=" 0 0 0" xyz="0 0 0" />
            <geometry>
                <box size="0.4 0.2 0.1" />
            </geometry>
        </collision>
        <visual name="chassis_visual">
            <origin rpy=" 0 0 0" xyz="0 0 0" />
            <geometry>
                <box size="0.4 0.2 0.1" />
            </geometry>
        </visual>
        <!--collision name='caster_collision'>
      <origin xyz="-0.15 0 -0.05" rpy=" 0 0 0"/>
      <geometry>
        <sphere radius="0.05"/>
      </geometry>
      <surface>
        <friction>
          <ode>
            <mu>0</mu>
            <mu2>0</mu2>
            <slip1>1.0</slip1>
            <slip2>1.0</slip2>
          </ode>
        </friction>
      </surface>
    </collision>

    <visual name='caster_visual'>
      <origin xyz="-0.15 0 -0.05" rpy=" 0 0 0"/>
      <geometry>
        <sphere radius="0.05"/>
      </geometry>
    </visual-->
    </link>
    <link name="left_wheel_help">
        <collision>
            <origin rpy="0 1.5707 1.5707" xyz="0 0 0" />
            <geometry>
                <cylinder length="0.05" radius="0.1" />
            </geometry>
        </collision>
        <visual>
            <origin rpy="0 1.5707 1.5707" xyz="0 0 0" />
            <geometry>
                <cylinder length="0.05" radius="0.1" />
            </geometry>
        </visual>
        
<inertial>
            <origin rpy="0 1.5707 1.5707" xyz="0 0 0" />
            <mass value="5" />
            <cylinder_inertia h="0.05" m="5" r="0.1" />
            <inertia ixx="1.0" ixy="0.0" ixz="0.0" iyy="1.0" iyz="0.0" izz="1.0" />
        </inertial>

    </link>
    <link name="right_wheel_help">
        <collision>
            <origin rpy="0 1.5707 1.5707" xyz="0 0 0" />
            <geometry>
                <cylinder length="0.05" radius="0.1" />
            </geometry>
        </collision>
        <visual>
            <origin rpy="0 1.5707 1.5707" xyz="0 0 0" />
            <geometry>
                <cylinder length="0.05" radius="0.1" />
            </geometry>
        </visual>
        
<inertial>
            <origin rpy="0 1.5707 1.5707" xyz="0 0 0" />
            <mass value="5" />
            <cylinder_inertia h="0.05" m="5" r="0.1" />
            <inertia ixx="1.0" ixy="0.0" ixz="0.0" iyy="1.0" iyz="0.0" izz="1.0" />
        </inertial>

    </link>
    <link name="left_wheel">
        <!--origin xyz="0.1 0.13 0.1" rpy="0 1.5707 1.5707"/-->
        <collision name="collision">
            <origin rpy="0 1.5707 1.5707" xyz="0 0 0" />
            <geometry>
                <cylinder length="0.05" radius="0.1" />
            </geometry>
        </collision>
        <visual name="left_wheel_visual">
            <origin rpy="0 1.5707 1.5707" xyz="0 0 0" />
            <geometry>
                <cylinder length="0.05" radius="0.1" />
            </geometry>
        </visual>
        
<inertial>
            <origin rpy="0 1.5707 1.5707" xyz="0 0 0" />
            <mass value="5" />
            <cylinder_inertia h="0.05" m="5" r="0.1" />
            <inertia ixx="1.0" ixy="0.0" ixz="0.0" iyy="1.0" iyz="0.0" izz="1.0" />
        </inertial>

    </link>
    <link name="right_wheel">
        <!--origin xyz="0.1 -0.13 0.1" rpy="0 1.5707 1.5707"/-->
        <collision name="collision">
            <origin rpy="0 1.5707 1.5707" xyz="0 0 0" />
            <geometry>
                <cylinder length="0.05" radius="0.1" />
            </geometry>
        </collision>
        <visual name="right_wheel_visual">
            <origin rpy="0 1.5707 1.5707" xyz="0 0 0" />
            <geometry>
                <cylinder length="0.05" radius="0.1" />
            </geometry>
        </visual>
        
<inertial>
            <origin rpy="0 1.5707 1.5707" xyz="0 0 0" />
            <mass value="5" />
            <cylinder_inertia h="0.05" m="5" r="0.1" />
            <inertia ixx="1.0" ixy="0.0" ixz="0.0" iyy="1.0" iyz="0.0" izz="1.0" />
        </inertial>

    </link>
    <link name="link">
        <!--collision>
	  <origin xyz="0 0 0" rpy="0 0 0"/>
      <geometry>
        <box size="0.073000 0.276000 0.072000"/> 
      </geometry>
    </collision-->
        <!--visual>
	  <origin xyz="0 0 0" rpy=" 0 0 0"/>
      <geometry>
        <mesh filename="package://mybot_description/meshes/kinect.dae"/-->
        <!--box size="0.073000 0.276000 0.072000"/-->
        <!--/geometry>
    </visual-->
        
<inertial>
            <mass value="0.001" />
            <origin rpy="0 0 0" xyz="0 0 0" />
            <inertia ixx="0.01" ixy="0.0" ixz="0.0" iyy="0.01" iyz="0.0" izz="0.01" />
        </inertial>

    </link>
    <!-- Hokuyo Laser -->
    <link name="hokuyo">
        <!--collision>
      <origin xyz="0 0 0" rpy="0 0 0"/>
      <geometry>
    	<box size="0.1 0.1 0.1"/>
      </geometry>
    </collision>

    <visual>
      <origin xyz="0 0 0" rpy="0 0 0"/>
      <geometry>
        <mesh filename="package://mybot_description/meshes/hokuyo.dae"/>
      </geometry>
    </visual-->
        
<inertial>
            <mass value="1e-5" />
            <origin rpy="0 0 0" xyz="0 0 0" />
            <inertia ixx="1e-6" ixy="0" ixz="0" iyy="1e-6" iyz="0" izz="1e-6" />
        </inertial>

    </link>
    <!--     ARM              -->
    <link name="arm_base_plate">
        <!--collision>
      <origin xyz="0 0 0" rpy="0 1.57 1.57"/>
      <geometry>
        <cylinder radius="0.01" length="0.01"/>
      </geometry>
    </collision>
    <visual>
      <origin xyz="0 0 0" rpy="0 1.57 1.57"/>
      <geometry>
        <cylinder radius="0.01" length="0.01"/>
      </geometry>
    </visual-->
        
<inertial>
            <origin rpy="0 1.57 1.57" xyz="0 0 0" />
            <mass value="0.001" />
            <cylinder_inertia h="0.01" m="5" r="0.01" />
            <inertia ixx="1.0" ixy="0.0" ixz="0.0" iyy="1.0" iyz="0.0" izz="1.0" />
        </inertial>

    </link>
    <link name="arm_1">
        <pose>0 0 0 0 0 0</pose>
        
<inertial>
            <mass value="0.003" />
            <origin rpy="0 0 0" xyz="-0.15 0 0" />
            <inertia ixx="0.5" ixy="0" ixz="0" iyy="1.0" iyz="0" izz="0.1" />
        </inertial>

        <collision>
            <origin rpy="0 0 0" xyz="-0.15 0 0" />
            <geometry>
                <box size=".3 .05 .05" />
            </geometry>
        </collision>
        <visual>
            <origin rpy="0 0 0" xyz="-0.15 0 0" />
            <geometry>
                <box size=".3 .05 .05" />
            </geometry>
        </visual>
    </link>
    <link name="arm_connector_1">
        
<inertial>
            <mass value="0.001" />
            <origin rpy=" 0 0 0" xyz="0.0 0 0" />
            <inertia ixx="0.5" ixy="0" ixz="0" iyy="1.0" iyz="0" izz="0.1" />
        </inertial>

        <collision>
            <geometry>
                <box size=".01 0.05 0.1" />
            </geometry>
        </collision>
        <visual>
            <origin rpy=" 0 0 0" xyz="0 0 0" />
            <geometry>
                <box size=".01 0.05 0.1" />
            </geometry>
        </visual>
    </link>
    <link name="arm_2">
        
<inertial>
            <mass value="0.002" />
            <origin rpy=" 0 0 0" xyz="0.155 0 0" />
            <inertia ixx="0.5" ixy="0" ixz="0" iyy="1.0" iyz="0" izz="0.1" />
        </inertial>

        <collision>
            <origin rpy="0 0 0" xyz="0.155 0 0" />
            <geometry>
                <box size=".3 .05 .05" />
            </geometry>
        </collision>
        <visual>
            <origin rpy="0 0 0" xyz="0.155 0 0" />
            <geometry>
                <box size=".3 .05 .05" />
            </geometry>
        </visual>
    </link>
    <link name="hand_base_plate">
        <!--collision>
      <origin xyz="0 0 0" rpy="0 1.57 0"/>
      <geometry>
        <cylinder radius="0.01" length="0.01"/>
      </geometry>
    </collision>
    <visual>
      <origin xyz="0 0 0" rpy="0 1.57 0"/>
      <geometry>
        <cylinder radius="0.01" length="0.01"/>
      </geometry>
    </visual-->
        
<inertial>
            <origin rpy="0 1.57 0" xyz="0 0 0" />
            <mass value="0.001" />
            <cylinder_inertia h="0.01" m="5" r="0.01" />
            <inertia ixx="1.0" ixy="0.0" ixz="0.0" iyy="1.0" iyz="0.0" izz="1.0" />
        </inertial>

    </link>
    <joint name="root_joint" type="fixed">
        <parent link="root" />
        <child link="chassis" />
    </joint>
    <joint name="gripper_extension_1" type="continuous">
        <axis xyz="0 0 1" />
        <parent link="chassis" />
        <child link="arm_base_plate" />
        <origin rpy="0 0 0" xyz="0.1 0 0.075" />
    </joint>
    <joint name="gripper_extension_2" type="revolute">
        <axis xyz="0 0 -1" />
        <limit effort="30" lower="0" upper="3.14" velocity="0.5" />
        <parent link="arm_base_plate" />
        <child link="arm_1" />
        <origin rpy="1.571 0 0" xyz="-0.01 0 0" />
    </joint>
    <joint name="gripper_extension_3" type="continuous">
        <origin rpy="1.571 0 0" xyz="-0.305 0.025 0" />
        <parent link="arm_1" />
        <child link="arm_connector_1" />
    </joint>
    <joint name="gripper_extension_4" type="revolute">
        <axis xyz="0 0 1" />
        <limit effort="30" lower="0" upper="3.14" velocity="0.5" />
        <parent link="arm_connector_1" />
        <child link="arm_2" />
        <origin rpy="-1.571 0 0" xyz="0 0 -0.03" />
    </joint>
    <joint name="gripper_extension_5" type="continuous">
        <axis xyz="1 0 0" />
        <parent link="arm_2" />
        <child link="hand_base_plate" />
        <origin rpy="0 0 0" xyz="0.31 0 0" />
    </joint>
    <joint name="camera_joint" type="fixed">
        <axis xyz="0 0 0" />
        <origin rpy="0 0 0" xyz="0.2 0 0.1" />
        <parent link="chassis" />
        <child link="link" />
    </joint>
    <joint name="hokuyo_joint" type="fixed">
        <axis xyz="0 1 0" />
        <origin rpy="0 0 0" xyz="0.2 0 0.2" />
        <parent link="chassis" />
        <child link="hokuyo" />
    </joint>
    <joint name="left_wheel_hinge" type="continuous">
        <origin rpy="0 0 0" xyz="0.15 0.15 0" />
        <child link="left_wheel" />
        <parent link="chassis" />
        <axis rpy="0 0 0" xyz="0 1 0" />
        <limit effort="100" velocity="100" />
        <joint_properties damping="0.0" friction="0.0" />
    </joint>
    <joint name="right_wheel_hinge" type="continuous">
        <origin rpy="0 0 0" xyz="0.15 -0.15 0" />
        <child link="right_wheel" />
        <parent link="chassis" />
        <axis rpy="0 0 0" xyz="0 1 0" />
        <limit effort="100" velocity="100" />
        <joint_properties damping="0.0" friction="0.0" />
    </joint>
    <joint name="left_wheel_help_hinge" type="continuous">
        <origin rpy="0 0 0" xyz="-0.15 0.15 0" />
        <child link="left_wheel_help" />
        <parent link="chassis" />
        <axis rpy="0 0 0" xyz="0 1 0" />
        <limit effort="100" velocity="100" />
        <joint_properties damping="0.0" friction="0.0" />
    </joint>
    <joint name="right_wheel_help_hinge" type="continuous">
        <origin rpy="0 0 0" xyz="-0.15 -0.15 0" />
        <child link="right_wheel_help" />
        <parent link="chassis" />
        <axis rpy="0 0 0" xyz="0 1 0" />
        <limit effort="100" velocity="100" />
        <joint_properties damping="0.0" friction="0.0" />
    </joint>
    <!-- Hier kommt der Gripper -->
    <link name="palm">
        
<inertial>
            <origin rpy="0 0 0" xyz="0 0 0" />
            <inertia ixx="0.01" ixy="0.0" ixz="0.0" iyy="0.01" iyz="0.0" izz="0.01" />
            <mass value="0.001" />
        </inertial>

        <collision>
            <origin rpy="0 0 0" xyz="0 0 0" />
            <geometry>
                <box size="0.01 0.02 0.01" />
            </geometry>
        </collision>
        <visual>
            <origin rpy="0 0 0" xyz="0 0 0" />
            <geometry>
                <box size="0.01 0.02 0.01" />
            </geometry>
        </visual>
    </link>
    <link name="left_finger">
        
<inertial>
            <origin rpy="0 0 -0.78539" xyz="0.01 0.02 0" />
            <inertia ixx="0.01" ixy="0.0" ixz="0.0" iyy="0.01" iyz="0.0" izz="0.01" />
            <mass value="0.005" />
        </inertial>

        <collision>
            <origin rpy="0 0 -0.78539" xyz="0.01 0.02 0" />
            <geometry>
                <box size="0.01 0.03 0.01" />
            </geometry>
        </collision>
        <visual>
            <origin rpy="0 0 -0.78539" xyz="0.01 0.02 0" />
            <geometry>
                <box size="0.01 0.03 0.01" />
            </geometry>
        </visual>
    </link>
    <link name="left_finger_tip">
        
<inertial>
            <origin rpy="0 0 1.5707" xyz="0.0336 0.03 0.005" />
            <inertia ixx="0.01" ixy="0.0" ixz="0.0" iyy="0.01" iyz="0.0" izz="0.01" />
            <mass value="0.001" />
        </inertial>

        <collision>
            <origin rpy="0 0 1.5707" xyz="0.0336 0.03 0.005" />
            <geometry>
                <box size="0.01 0.02 0.01" />
            </geometry>
        </collision>
        <visual>
            <origin rpy="0 0 1.5707" xyz="0.0336 0.03 0.005" />
            <geometry>
                <box size="0.01 0.02 0.01" />
            </geometry>
        </visual>
    </link>
    <link name="right_finger">
        
<inertial>
            <origin rpy="0 0 .78539" xyz="0.01 -0.02 0" />
            <inertia ixx="0.01" ixy="0.0" ixz="0.0" iyy="0.01" iyz="0.0" izz="0.01" />
            <mass value="0.001" />
        </inertial>

        <collision>
            <origin rpy="0 0 .78539" xyz="0.01 -0.02 0" />
            <geometry>
                <box size="0.01 0.03 0.01" />
            </geometry>
        </collision>
        <visual>
            <origin rpy="0 0 .78539" xyz="0.01 -0.02 0" />
            <geometry>
                <box size="0.01 0.03 0.01" />
            </geometry>
        </visual>
    </link>
    <link name="right_finger_tip">
        <origin rpy="0 0 1.5707" xyz="0.0336 -0.03 0.005" />
        
<inertial>
            <inertia ixx="0.01" ixy="0.0" ixz="0.0" iyy="0.01" iyz="0.0" izz="0.01" />
            <mass value="0.001" />
        </inertial>

        <collision>
            <origin rpy="0 0 1.5707" xyz="0.0336 -0.03 0.005" />
            <geometry>
                <box size="0.01 0.02 0.01" />
            </geometry>
        </collision>
        <visual>
            <origin rpy="0 0 1.5707" xyz="0.0336 -0.03 0.005" />
            <geometry>
                <box size="0.01 0.02 0.01" />
            </geometry>
        </visual>
    </link>
    <joint name="arm_baser" type="revolute">
        <axis rpy="0 0 0" xyz="0 1 0" />
        <child link="palm" />
        <parent link="hand_base_plate" />
        <origin rpy="0 0 0" xyz="0.01 0 0" />
        <limit effort="30" lower="-1" upper="1" velocity="0.5" />
    </joint>
    <joint name="palm_left_finger" type="revolute">
        <child link="left_finger" />
        <parent link="palm" />
        <axis rpy="0 0 0" xyz="0 0 1" />
        <limit effort="30" lower="-0.4" upper="0.4" velocity="0.5" />
    </joint>
    <joint name="left_finger_tip" type="revolute">
        <child link="left_finger_tip" />
        <parent link="left_finger" />
        <axis rpy="0 0 0" xyz="0 0 1" />
        <limit effort="30" lower="-0.4" upper="0.4" velocity="0.5" />
    </joint>
    <joint name="palm_right_finger" type="revolute">
        <child link="right_finger" />
        <parent link="palm" />
        <axis rpy="0 0 0" xyz="0 0 1" />
        <limit effort="30" lower="-0.4" upper="0.4" velocity="0.5" />
    </joint>
    <joint name="right_finger_tip" type="revolute">
        <child link="right_finger_tip" />
        <parent link="right_finger" />
        <axis rpy="0 0 0" xyz="0 0 1" />
        <limit effort="30" lower="-0.4" upper="0.4" velocity="0.5" />
    </joint>
    <gazebo>
        <selfCollide>true</selfCollide>
    </gazebo>
    <transmission name="trans_gripper_extension_1">
        <type>transmission_interface/SimpleTransmission</type>
        <joint name="gripper_extension_1">
            <hardwareInterface>hardware_interface/PositionJointInterface</hardwareInterface>
        </joint>
        <actuator name="gripper_extension_1_motor">
            <hardwareInterface>hardware_interface/PositionJointInterface</hardwareInterface>
            <mechanicalReduction>1</mechanicalReduction>
        </actuator>
    </transmission>
    <transmission name="trans_gripper_extension_2">
        <type>transmission_interface/SimpleTransmission</type>
        <joint name="gripper_extension_2">
            <hardwareInterface>hardware_interface/PositionJointInterface</hardwareInterface>
        </joint>
        <actuator name="gripper_extension_2_motor">
            <hardwareInterface>hardware_interface/PositionJointInterface</hardwareInterface>
            <mechanicalReduction>1</mechanicalReduction>
        </actuator>
    </transmission>
    <transmission name="trans_gripper_extension_3">
        <type>transmission_interface/SimpleTransmission</type>
        <joint name="gripper_extension_3">
            <hardwareInterface>hardware_interface/PositionJointInterface</hardwareInterface>
        </joint>
        <actuator name="gripper_extension_3_motor">
            <hardwareInterface>hardware_interface/PositionJointInterface</hardwareInterface>
            <mechanicalReduction>1</mechanicalReduction>
        </actuator>
    </transmission>
    <transmission name="trans_gripper_extension_4">
        <type>transmission_interface/SimpleTransmission</type>
        <joint name="gripper_extension_4">
            <hardwareInterface>hardware_interface/PositionJointInterface</hardwareInterface>
        </joint>
        <actuator name="gripper_e No p gain specified for pid.  Namespace: /gazebo_ros_control/pid_gains/gripper_extension_1
xtension_4_motor">
            <hardwareInterface>hardware_interface/PositionJointInterface</hardwareInterface>
            <mechanicalReduction>1</mechanicalReduction>
        </actuator>
    </transmission>
    <transmission name="trans_gripper_extension_5">
        <type>transmission_interface/SimpleTransmission</type>
        <joint name="gripper_extension_5">
            <hardwareInterface>hardware_interface/PositionJointInterface</hardwareInterface>
        </joint>
        <actuator name="gripper_extension_5_motor">
            <hardwareInterface>hardware_interface/PositionJointInterface</hardwareInterface>
            <mechanicalReduction>1</mechanicalReduction>
        </actuator>
    </transmission>
    <transmission name="trans_left_wheel_hinge">
        <type>transmission_interface/SimpleTransmission</type>
        <joint name="left_wheel_hinge">
            <hardwareInterface>hardware_interface/EffortJointInterface</hardwareInterface>
        </joint>
        <actuator name="left_wheel_hinge_motor">
            <hardwareInterface>hardware_interface/EffortJointInterface</hardwareInterface>
            <mechanicalReduction>1</mechanicalReduction>
        </actuator>
    </transmission>
    <transmission name="trans_right_wheel_hinge">
        <type>transmission_interface/SimpleTransmission</type>
        <joint name="right_wheel_hinge">
            <hardwareInterface>hardware_interface/EffortJointInterface</hardwareInterface>
        </joint>
        <actuator name="right_wheel_hinge_motor">
            <hardwareInterface>hardware_interface/EffortJointInterface</hardwareInterface>
            <mechanicalReduction>1</mechanicalReduction>
        </actuator>
    </transmission>
    <transmission name="trans_left_wheel_help_hinge">
        <type>transmission_interface/SimpleTransmission</type>
        <joint name="left_wheel_help_hinge">
            <hardwareInterface>hardware_interface/EffortJointInterface</hardwareInterface>
        </joint>
        <actuator name="left_wheel_help_hinge_motor">
            <hardwareInterface>hardware_interface/EffortJointInterface</hardwareInterface>
            <mechanicalReduction>1</mechanicalReduction>
        </actuator>
    </transmission>
    <transmission name="trans_right_wheel_help_hinge">
        <type>transmission_interface/SimpleTransmission</type>
        <joint name="right_wheel_help_hinge">
            <hardwareInterface>hardware_interface/EffortJointInterface</hardwareInterface>
        </joint>
        <actuator name="right_wheel_help_hinge_motor">
            <hardwareInterface>hardware_interface/EffortJointInterface</hardwareInterface>
            <mechanicalReduction>1</mechanicalReduction>
        </actuator>
    </transmission>
    <transmission name="trans_arm_baser">
        <type>transmission_interface/SimpleTransmission</type>
        <joint name="arm_baser">
            <hardwareInterface>hardware_interface/PositionJointInterface</hardwareInterface>
        </joint>
        <actuator name="arm_baser_motor">
            <hardwareInterface>hardware_interface/PositionJointInterface</hardwareInterface>
            <mechanicalReduction>1</mechanicalReduction>
        </actuator>
    </transmission>
    <transmission name="trans_palm_left_finger">
        <type>transmission_interface/SimpleTransmission</type>
        <joint name="palm_left_finger">
            <hardwareInterface>hardware_interface/PositionJointInterface</hardwareInterface>
        </joint>
        <actuator name="palm_left_finger_motor">
            <hardwareInterface>hardware_interface/PositionJointInterface</hardwareInterface>
            <mechanicalReduction>1</mechanicalReduction>
        </actuator>
    </transmission>
    <transmission name="trans_left_finger_tip">
        <type>transmission_interface/SimpleTransmission</type>
        <joint name="left_finger_tip">
            <hardwareInterface>hardware_interface/PositionJointInterface</hardwareInterface>
        </joint>
        <actuator name="left_finger_tip_motor">
            <hardwareInterface>hardware_interface/PositionJointInterface</hardwareInterface>
            <mechanicalReduction>1</mechanicalReduction>
        </actuator>
    </transmission>
    <transmission name="trans_palm_right_finger">
        <type>transmission_interface/SimpleTransmission</type>
        <joint name="palm_right_finger">
            <hardwareInterface>hardware_interface/PositionJointInterface</hardwareInterface>
        </joint>
        <actuator name="palm_right_finger_motor">
            <hardwareInterface>hardware_interface/PositionJointInterface</hardwareInterface>
            <mechanicalReduction>1</mechanicalReduction>
        </actuator>
    </transmission>
    <transmission name="trans_right_finger_tip">
        <type>transmission_interface/SimpleTransmission</type>
        <joint name="right_finger_tip">
            <hardwareInterface>hardware_interface/PositionJointInterface</hardwareInterface>
        </joint>
        <actuator name="right_finger_tip_motor">
            <hardwareInterface>hardware_interface/PositionJointInterface</hardwareInterface>
            <mechanicalReduction>1</mechanicalReduction>
        </actuator>
    </transmission>
    <gazebo>
        <plugin name="gazebo_ros_control" filename="libgazebo_ros_control.so">
        </plugin>
    </gazebo>
	<gazebo>
        <plugin filename="libgazebo_ros_diff_drive.so" name="differential_drive_controller">
            <legacyMode>false</legacyMode>
            <alwaysOn>true</alwaysOn>
            <updateRate>20</updateRate>
            <leftJoint>left_wheel_hinge</leftJoint>
            <rightJoint>right_wheel_hinge</rightJoint>
            <wheelSeparation>0.4</wheelSeparation>
            <wheelDiameter>0.1</wheelDiameter>
            <wheelTorque>50</wheelTorque>
            <wheelAcceleration>1</wheelAcceleration>
            <commandTopic>cmd_vel</commandTopic>
            <odometryTopic>odom</odometryTopic>
            <odometryFrame>map</odometryFrame>
            <robotBaseFrame>root</robotBaseFrame>
            <publishWheelTF>true</publishWheelTF>
            <publishOdomTF>true</publishOdomTF>
            <publishWheelJointState>true</publishWheelJointState>
            <publishTf>1</publishTf>
            <rosDebugLevel>1</rosDebugLevel>
        </plugin>
    </gazebo>
    <gazebo reference="chassis">
        <material>Gazebo/Orange</material>
        <selfCollide>true</selfCollide>
    </gazebo>
    <gazebo reference="left_wheel">
        <material>Gazebo/Blue</material>
    </gazebo>
    <gazebo reference="right_wheel">
        <material>Gazebo/Blue</material>
    </gazebo>
    <gazebo reference="left_wheel_help">
        <material>Gazebo/Blue</material>
    </gazebo>
    <gazebo reference="right_wheel_help">
        <material>Gazebo/Blue</material>
    </gazebo>
    <gazebo reference="arm_fix">
        <material>Gazebo/Blue</material>
    </gazebo>
    <gazebo reference="link">
        <sensor name="camera" type="depth">
            <pose>0 0 0 0 0 0</pose>
            <update_rate>30</update_rate>
            <camera>
                <horizontal_fov>1.047198</horizontal_fov>
                <image>
                    <width>1080</width>
                    <height>720</height>
                    <format>R8G8B8</format>
                </image>
                <clip>
                    <near>0.01</near>
                    <far>25</far>
                </clip>
            </camera>
            <plugin filename="libgazebo_ros_openni_kinect.so" name="camera_plugin">
                <baseline>0.2</baseline>
                <always_on>1</always_on>
                <updateRate>0.0</updateRate>
                <cameraName>camera</cameraName>
                <imageTopicName>/camera/color/image_raw</imageTopicName>
                <cameraInfoTopicName>/camera/color/camera_info</cameraInfoTopicName>
                <depthImageTopicName>/camera/depth/image_raw</depthImageTopicName>
                <depthImageCameraInfoTopicName>/camera/depth/camera_info</depthImageCameraInfoTopicName>
                <pointCloudTopicName>/camera/depth/points</pointCloudTopicName>
                <frameName>link</frameName>
                <pointCloudCutoff>0.5</pointCloudCutoff>
                <pointCloudCutoffMax>3.0</pointCloudCutoffMax>
                <distortionK1>0</distortionK1>
                <distortionK2>0</distortionK2>
                <distortionK3>0</distortionK3>
                <distortionT1>0</distortionT1>
                <distortionT2>0</distortionT2>
                <CxPrime>0</CxPrime>
                <Cx>0</Cx>
                <Cy>0</Cy>
                <focalLength>0</focalLength>
                <hackBaseline>0</hackBaseline>
            </plugin>
        </sensor>
    </gazebo>
    <gazebo reference="hokuyo">
        <sensor name="head_hokuyo_sensor" type="gpu_ray">
            <pose>0 0 0 0 0 0</pose>
            <visualize>false</visualize>
            <update_rate>20</update_rate>
            <ray>
                <scan>
                    <horizontal>
                        <samples>720</samples>
                        <resolution>1</resolution>
                        <min_angle>-1.5</min_angle>
                        <max_angle>1.5</max_angle>
                    </horizontal>
                </scan>
                <range>
                    <min>0.10</min>
                    <max>20.0</max>
                    <resolution>0.01</resolution>
                </range>
                <noise>
                    <type>gaussian</type>
                    <!-- Noise parameters based on published spec for Hokuyo laser
               achieving "+-30mm" accuracy at range < 10m.  A mean of 0.0m and
               stddev of 0.01m will put 99.7% of samples within 0.03m of the true
               reading. -->
                    <mean>0.0</mean>
                    <stddev>0.01</stddev>
                </noise>
            </ray>
            <plugin filename="libgazebo_ros_gpu_laser.so" name="gazebo_ros_head_hokuyo_controller">
                <topicName>/mybot/laser/scan</topicName>
                <frameName>hokuyo</frameName>
            </plugin>
        </sensor>
    </gazebo>
</robot>
